Sender: LSF System <lsfadmin@eu-g3-018>
Subject: Job 219871805: <python train.py --dataset apple> in cluster <euler> Exited

Job <python train.py --dataset apple> was submitted from host <eu-login-10> by user <shiyang> in cluster <euler> at Fri May 27 15:04:58 2022
Job was executed on host(s) <4*eu-g3-018>, in queue <gpu.24h>, as user <shiyang> in cluster <euler> at Fri May 27 15:05:23 2022
</cluster/home/shiyang> was used as the home directory.
</cluster/home/shiyang/votenet-pmlr> was used as the working directory.
Started at Fri May 27 15:05:23 2022
Terminated at Sat May 28 15:05:30 2022
Results reported at Sat May 28 15:05:30 2022

Your job looked like:

------------------------------------------------------------
# LSBATCH: User input
python train.py --dataset apple
------------------------------------------------------------

TERM_RUNLIMIT: job killed after reaching LSF run time limit.
Exited with exit code 140.

Resource usage summary:

    CPU time :                                   107.00 sec.
    Max Memory :                                 2937 MB
    Average Memory :                             2934.73 MB
    Total Requested Memory :                     32768.00 MB
    Delta Memory :                               29831.00 MB
    Max Swap :                                   -
    Max Processes :                              6
    Max Threads :                                16
    Run time :                                   86406 sec.
    Turnaround time :                            86432 sec.

The output (if any) follows:

Retry attempt failed:
Traceback (most recent call last):
  File "/cluster/home/shiyang/votenet-pmlr/venv-votenet/lib64/python3.7/site-packages/urllib3/connection.py", line 175, in _new_conn
    (self._dns_host, self.port), self.timeout, **extra_kw
  File "/cluster/home/shiyang/votenet-pmlr/venv-votenet/lib64/python3.7/site-packages/urllib3/util/connection.py", line 95, in create_connection
    raise err
  File "/cluster/home/shiyang/votenet-pmlr/venv-votenet/lib64/python3.7/site-packages/urllib3/util/connection.py", line 85, in create_connection
    sock.connect(sa)
ConnectionRefusedError: [Errno 111] Connection refused

During handling of the above exception, another exception occurred:

Traceback (most recent call last):
  File "/cluster/home/shiyang/votenet-pmlr/venv-votenet/lib64/python3.7/site-packages/urllib3/connectionpool.py", line 710, in urlopen
    chunked=chunked,
  File "/cluster/home/shiyang/votenet-pmlr/venv-votenet/lib64/python3.7/site-packages/urllib3/connectionpool.py", line 386, in _make_request
    self._validate_conn(conn)
  File "/cluster/home/shiyang/votenet-pmlr/venv-votenet/lib64/python3.7/site-packages/urllib3/connectionpool.py", line 1040, in _validate_conn
    conn.connect()
  File "/cluster/home/shiyang/votenet-pmlr/venv-votenet/lib64/python3.7/site-packages/urllib3/connection.py", line 358, in connect
    self.sock = conn = self._new_conn()
  File "/cluster/home/shiyang/votenet-pmlr/venv-votenet/lib64/python3.7/site-packages/urllib3/connection.py", line 187, in _new_conn
    self, "Failed to establish a new connection: %s" % e
urllib3.exceptions.NewConnectionError: <urllib3.connection.HTTPSConnection object at 0x2b5e63a096d0>: Failed to establish a new connection: [Errno 111] Connection refused

During handling of the above exception, another exception occurred:

Traceback (most recent call last):
  File "/cluster/home/shiyang/votenet-pmlr/venv-votenet/lib64/python3.7/site-packages/requests/adapters.py", line 450, in send
    timeout=timeout
  File "/cluster/home/shiyang/votenet-pmlr/venv-votenet/lib64/python3.7/site-packages/urllib3/connectionpool.py", line 786, in urlopen
    method, url, error=e, _pool=self, _stacktrace=sys.exc_info()[2]
  File "/cluster/home/shiyang/votenet-pmlr/venv-votenet/lib64/python3.7/site-packages/urllib3/util/retry.py", line 592, in increment
    raise MaxRetryError(_pool, url, error or ResponseError(cause))
urllib3.exceptions.MaxRetryError: HTTPSConnectionPool(host='api.wandb.ai', port=443): Max retries exceeded with url: /graphql (Caused by NewConnectionError('<urllib3.connection.HTTPSConnection object at 0x2b5e63a096d0>: Failed to establish a new connection: [Errno 111] Connection refused'))

During handling of the above exception, another exception occurred:

Traceback (most recent call last):
  File "/cluster/home/shiyang/votenet-pmlr/venv-votenet/lib64/python3.7/site-packages/wandb/sdk/lib/retry.py", line 102, in __call__
    result = self._call_fn(*args, **kwargs)
  File "/cluster/home/shiyang/votenet-pmlr/venv-votenet/lib64/python3.7/site-packages/wandb/sdk/internal/internal_api.py", line 140, in execute
    return self.client.execute(*args, **kwargs)
  File "/cluster/home/shiyang/votenet-pmlr/venv-votenet/lib64/python3.7/site-packages/wandb/vendor/gql-0.2.0/wandb_gql/client.py", line 52, in execute
    result = self._get_result(document, *args, **kwargs)
  File "/cluster/home/shiyang/votenet-pmlr/venv-votenet/lib64/python3.7/site-packages/wandb/vendor/gql-0.2.0/wandb_gql/client.py", line 60, in _get_result
    return self.transport.execute(document, *args, **kwargs)
  File "/cluster/home/shiyang/votenet-pmlr/venv-votenet/lib64/python3.7/site-packages/wandb/vendor/gql-0.2.0/wandb_gql/transport/requests.py", line 38, in execute
    request = requests.post(self.url, **post_args)
  File "/cluster/home/shiyang/votenet-pmlr/venv-votenet/lib64/python3.7/site-packages/requests/api.py", line 117, in post
    return request('post', url, data=data, json=json, **kwargs)
  File "/cluster/home/shiyang/votenet-pmlr/venv-votenet/lib64/python3.7/site-packages/requests/api.py", line 61, in request
    return session.request(method=method, url=url, **kwargs)
  File "/cluster/home/shiyang/votenet-pmlr/venv-votenet/lib64/python3.7/site-packages/requests/sessions.py", line 529, in request
    resp = self.send(prep, **send_kwargs)
  File "/cluster/home/shiyang/votenet-pmlr/venv-votenet/lib64/python3.7/site-packages/requests/sessions.py", line 645, in send
    r = adapter.send(request, **kwargs)
  File "/cluster/home/shiyang/votenet-pmlr/venv-votenet/lib64/python3.7/site-packages/requests/adapters.py", line 519, in send
    raise ConnectionError(e, request=request)
requests.exceptions.ConnectionError: HTTPSConnectionPool(host='api.wandb.ai', port=443): Max retries exceeded with url: /graphql (Caused by NewConnectionError('<urllib3.connection.HTTPSConnection object at 0x2b5e63a096d0>: Failed to establish a new connection: [Errno 111] Connection refused'))
wandb: Network error (ConnectionError), entering retry loop.
wandb: W&B API key is configured. Use `wandb login --relogin` to force relogin
322 361
41 46
wandb: Network error (ConnectionError), entering retry loop.
User defined signal 2
